<?xml version="1.0" ?>
<testsuite errors="1" failures="0" name="Control.Control-20151216104623" tests="1" time="0.000">
	<testcase classname="Control.Control" name="testSuit" time="0.000">
		<error message="&lt;module 'test' from '/home/muli/local/test/untitled/myunittest/testcase/test.pyc'&gt; is not callable" type="TypeError">
<![CDATA[Traceback (most recent call last):
  File "/home/muli/local/test/untitled/myunittest/testcase/Control.py", line 11, in testSuit
    suite.addTest(test)
  File "/usr/lib/python2.7/unittest/suite.py", line 49, in addTest
    raise TypeError("{} is not callable".format(repr(test)))
TypeError: <module 'test' from '/home/muli/local/test/untitled/myunittest/testcase/test.pyc'> is not callable
]]>		</error>
	</testcase>
	<system-out>
<![CDATA[]]>	</system-out>
	<system-err>
<![CDATA[]]>	</system-err>
</testsuite>
